Workbook

Sheet Summary
A1: KLIP Pre-Planned Shipment - Group Suggestions
A2: Source: test-klip.kpndomain.com - Unplanned contracts snapshot, generated 22 Jul 2026 (contract date range 01/01/2026 - 22/07/2026)
A3: Candidate set: contracts with no shipment yet, status Open, transport mode SEA/MIX, outstanding qty > 0, with delivery window.
A5: KEY FIGURES
A6: Contracts analysed (rows) | B6: =COUNTA('Group Suggestions'!G2:G93) -> 92
A7: Pre-Planned groups (distinct Group IDs) | B7: =SUMPRODUCT(1/COUNTIF('Group Suggestions'!A2:A93,'Group Suggestions'!A2:A93)) -> 84
A8: Contracts auto-grouped (AUTO-GROUP) | B8: =COUNTIF('Group Suggestions'!B2:B93,"AUTO-GROUP") -> 14
A9: Contracts left as single-contract groups | B9: =COUNTIF('Group Suggestions'!B2:B93,"SINGLE") -> 67
A10: Contracts excluded (Blank/Trading plant) | B10: =COUNTIF('Group Suggestions'!B2:B93,"EXCLUDED*") -> 11
A11: Total outstanding qty in scope (MT) | B11: =SUM('Group Suggestions'!S2:S93) -> 127773.71
A12: Outstanding qty auto-grouped (MT) | B12: =SUMIF('Group Suggestions'!B2:B93,"AUTO-GROUP",'Group Suggestions'!S2:S93) -> 10550
A14: GROUPING LOGIC (backtested at 85.7% pairwise precision; 86% of suggested multi-contract groups fully matched real shipments)
A15: 1. HARD KEY - contracts may share a vessel only if ALL match: Group Plant + Buyer + Incoterm + Product (100% invariants across all 187 historical shipments).
A16: 2. AUTO-GROUP - within a hard key, group contracts with the SAME SUPPLIER whose delivery windows are identical or within 3 days of each other.
A17: 3. CAPACITY - contract qty (MT) is packed into bins sized at the median historical vessel parcel for that Group Plant (Vessel Bin column). When the sum exceeds the bin, the cluster is split into multiple groups; Est. Vessels = CEILING(group qty / bin).
A18: 4. CIF stays single-contract unless rule 2 matches exactly (103 of 105 historical multi-contract shipments were FOB).
A19: 5. Tier-2 column lists other groups in the same hard key, same supplier group, window gap <= 7 days - candidates for MANUAL merge review only (~60-66% precision, do not auto-apply).
A20: Group ID format: PP-<PLANT>-<seq>. Rows with the same Group ID = one suggested vessel shipment. Green rows = auto-grouped; gray rows = excluded plants (Blank/Trading); amber/white banding separates single-contract groups.
A22: NOTES / ASSUMPTIONS
A23: Quantities converted from KG (as stored in KLIP contracts.quantity_ordered / outstanding) to MT. Grouping uses OUTSTANDING qty, since already-fulfilled volume does not need vessel space.
A24: Vessel Bin (MT) = median BL quantity of past non-cancelled shipments per Group Plant (Bontang 2,700 / Tanjung Pura 3,971 / Bulking Batam 2,998 / Karawang 1,000; fallback 3,000 where history is thin). Refresh monthly from shipment history.
A25: Backtest basis: 416 planned/completed contracts across 165 shipments on this environment, 22 Jul 2026. See docs/PRE-PLANNED-GROUPING-SPEC.md for the full spec and SQL.
A26: Contracts with very small outstanding (< ~100 MT, e.g. nearly-closed contracts) appear as singles; consider a minimum-qty filter before creating Pre-Planned shipments from them.

Sheet Group Suggestions
A1: Pre-Planned Group ID | B1: Group Type | C1: Contracts in Group | D1: Group Total Outstanding (MT) | E1: Vessel Bin (MT) | F1: Est. Vessels Needed | G1: Contract No | H1: Contract Ext No | I1: PO No | J1: Group Plant | K1: Buyer | L1: Incoterm | M1: Product | N1: Supplier | O1: Supplier Group | P1: LT / Spot | Q1: Transport Mode | R1: Contract Qty (MT) | S1: Outstanding Qty (MT) | T1: Contract Date | U1: Delivery Start | V1: Delivery End | W1: Tier-2: Review Merge With
A2: PP-BEKASI-001 | B2: SINGLE | C2: 1 | D2: 350 | E2: 3000 | F2: =MAX(1,CEILING(D2/E2,1)) -> 1 | G2: 1014002954 | H2: 1112000000992 | I2: 1011002954 | J2: Bekasi | K2: PRC PALM & LAURIC BEKASI | L2: FOB | M2: CPO | N2: BERKAT SAWIT UTAMA PT. | O2: INTERCO | P2: MB | Q2: SEA | R2: 350 | S2: 350 | T2: 46114 | U2: 46114 | V2: 46122 | W2: PP-BEKASI-002
A3: PP-BEKASI-002 | B3: SINGLE | C3: 1 | D3: 300 | E3: 3000 | F3: =MAX(1,CEILING(D3/E3,1)) -> 1 | G3: 1014002983 | H3: 1132000000540 | I3: 1011002983 | J3: Bekasi | K3: PRC PALM & LAURIC BEKASI | L3: FOB | M3: CPO | N3: SWADAYA INDOPALMA PT. | O3: INTERCO | P3: MB | Q3: SEA | R3: 300 | S3: 300 | T3: 46129 | U3: 46129 | V3: 46137 | W3: PP-BEKASI-001
A4: PP-BLANK-001 | B4: EXCLUDED (Blank/Trading plant) | C4: 1 | D4: 700 | E4: 3000 | F4: =MAX(1,CEILING(D4/E4,1)) -> 1 | G4: 9054100021 | H4: 1182000000342 | I4: 9051000021 | J4: Blank | K4: THIP TRADING PLANT 2 | L4: FOB | M4: CPO | N4: AGRIPRIMA CIPTA PERSADA PT. | O4: INTERCO | P4: MB | Q4: SEA | R4: 700 | S4: 700 | T4: 46114 | U4: 46121 | V4: 46122
A5: PP-BLANK-002 | B5: EXCLUDED (Blank/Trading plant) | C5: 1 | D5: 1500 | E5: 3000 | F5: =MAX(1,CEILING(D5/E5,1)) -> 1 | G5: 9054100019 | H5: 1182000000341 | I5: 9051000019 | J5: Blank | K5: THIP TRADING PLANT 2 | L5: FOB | M5: CPO | N5: AGRIPRIMA CIPTA PERSADA PT. | O5: INTERCO | P5: MB | Q5: SEA | R5: 1500 | S5: 1500 | T5: 46108 | U5: 46122 | V5: 46129
A6: PP-BLANK-003 | B6: EXCLUDED (Blank/Trading plant) | C6: 1 | D6: 1000 | E6: 3000 | F6: =MAX(1,CEILING(D6/E6,1)) -> 1 | G6: 9174100048 | H6: 1182000000345 | I6: 9171000048 | J6: Blank | K6: PABRIK WKSM | L6: FOB | M6: WASTE OIL (POME) | N6: AGRIPRIMA CIPTA PERSADA PT. | O6: INTERCO | P6: MB | Q6: SEA | R6: 1000 | S6: 1000 | T6: 46129 | U6: 46132 | V6: 46142
A7: PP-BLANK-004 | B7: EXCLUDED (Blank/Trading plant) | C7: 1 | D7: 1000 | E7: 3000 | F7: =MAX(1,CEILING(D7/E7,1)) -> 1 | G7: 9174100049 | H7: 1182000000347 | I7: 9171000049 | J7: Blank | K7: PABRIK WKSM | L7: FOB | M7: WASTE OIL (POME) | N7: AGRIPRIMA CIPTA PERSADA PT. | O7: INTERCO | P7: MB | Q7: SEA | R7: 1000 | S7: 1000 | T7: 46136 | U7: 46143 | V7: 46152
A8: PP-BLANK-005 | B8: EXCLUDED (Blank/Trading plant) | C8: 1 | D8: 300 | E8: 3000 | F8: =MAX(1,CEILING(D8/E8,1)) -> 1 | G8: 9234100075 | H8: 1192000000198 | I8: 9231000075 | J8: Blank | K8: PTW TRADING PLANT 2 | L8: FOB | M8: CPO | N8: AGRINUSA PERSADA MULIA PT. | O8: INTERCO | P8: MB | Q8: SEA | R8: 300 | S8: 300 | T8: 46122 | U8: 46143 | V8: 46152
A9: PP-BLANK-006 | B9: EXCLUDED (Blank/Trading plant) | C9: 1 | D9: 1800 | E9: 3000 | F9: =MAX(1,CEILING(D9/E9,1)) -> 1 | G9: 9334100045 | H9: 0529/BIN-CPO/SC-CMA/VI/26 | I9: 9330000045 | J9: Blank | K9: CMA TRADING PLANT 1 | L9: FOB | M9: CPO | N9: BUMI INDAWA NIAGA PT | O9: KORINDO | P9: FS | Q9: SEA | R9: 1800 | S9: 1800 | T9: 46190 | U9: 46218 | V9: 46221
A10: PP-BLANK-007 | B10: EXCLUDED (Blank/Trading plant) | C10: 1 | D10: 3200 | E10: 3200 | F10: =MAX(1,CEILING(D10/E10,1)) -> 1 | G10: 9194100034 | H10: 0528/BIN-CPO/SC-APM/VI/26 | I10: 9191000034 | J10: Blank | K10: APM TRADING PLANT 1 | L10: FOB | M10: CPO | N10: BUMI INDAWA NIAGA PT | O10: KORINDO | P10: FS | Q10: SEA | R10: 3200 | S10: 3200 | T10: 46190 | U10: 46218 | V10: 46221
A11: PP-BONTAN-001 | B11: SINGLE | C11: 1 | D11: 6 | E11: 3000 | F11: =MAX(1,CEILING(D11/E11,1)) -> 1 | G11: 1004028171 | H11: NJL/LCPKO/25/26/002 | I11: 1001028171 | J11: Bontang | K11: EUP EDIBLE OIL BONTANG | L11: CIF | M11: CPKO | N11: NUNUKAN JAYA LESTARI PT. | O11: ANUJALES | P11: FS | Q11: SEA | R11: 500 | S11: 5.53 | T11: 46079 | U11: 46088 | V11: 46091
A12: PP-BONTAN-002 | B12: SINGLE | C12: 1 | D12: 300 | E12: 3000 | F12: =MAX(1,CEILING(D12/E12,1)) -> 1 | G12: 1004030297 | H12: 1192000000210 | I12: 1001030297 | J12: Bontang | K12: EUP EDIBLE OIL BONTANG | L12: FOB | M12: CPO | N12: AGRINUSA PERSADA MULIA PT. | O12: INTERCO | P12: MB | Q12: SEA | R12: 300 | S12: 300 | T12: 46178 | U12: 46178 | V12: 46186 | W12: PP-BONTAN-003, PP-BONTAN-004, PP-BONTAN-005
A13: PP-BONTAN-003 | B13: SINGLE | C13: 1 | D13: 600 | E13: 3000 | F13: =MAX(1,CEILING(D13/E13,1)) -> 1 | G13: 1004030295 | H13: 1182000000356 | I13: 1001030295 | J13: Bontang | K13: EUP EDIBLE OIL BONTANG | L13: FOB | M13: CPO | N13: AGRIPRIMA CIPTA PERSADA PT. | O13: INTERCO | P13: MB | Q13: SEA | R13: 600 | S13: 600 | T13: 46178 | U13: 46178 | V13: 46186 | W13: PP-BONTAN-002, PP-BONTAN-004, PP-BONTAN-005
A14: PP-BONTAN-004 | B14: SINGLE | C14: 1 | D14: 600 | E14: 3000 | F14: =MAX(1,CEILING(D14/E14,1)) -> 1 | G14: 1004030474 | H14: 1192000000211 | I14: 1001030474 | J14: Bontang | K14: EUP EDIBLE OIL BONTANG | L14: FOB | M14: CPO | N14: AGRINUSA PERSADA MULIA PT. | O14: INTERCO | P14: MB | Q14: SEA | R14: 600 | S14: 600 | T14: 46185 | U14: 46188 | V14: 46203 | W14: PP-BONTAN-002, PP-BONTAN-003, PP-BONTAN-005, PP-BONTAN-011
A15: PP-BONTAN-005 | B15: SINGLE | C15: 1 | D15: 1500 | E15: 3000 | F15: =MAX(1,CEILING(D15/E15,1)) -> 1 | G15: 1004030473 | H15: 1182000000357 | I15: 1001030473 | J15: Bontang | K15: EUP EDIBLE OIL BONTANG | L15: FOB | M15: CPO | N15: AGRIPRIMA CIPTA PERSADA PT. | O15: INTERCO | P15: MB | Q15: SEA | R15: 1500 | S15: 1500 | T15: 46185 | U15: 46188 | V15: 46203 | W15: PP-BONTAN-002, PP-BONTAN-003, PP-BONTAN-004, PP-BONTAN-011
A16: PP-BONTAN-006 | B16: SINGLE | C16: 1 | D16: 700 | E16: 3000 | F16: =MAX(1,CEILING(D16/E16,1)) -> 1 | G16: 1004030265 | H16: 004/SIL-PK/PJB-EUP/VI/26 | I16: 1001030265 | J16: Bontang | K16: EUP EDIBLE OIL BONTANG | L16: FOB | M16: PK | N16: SEBAKIS INTI LESTARI PT. | O16: HARDAYA | P16: TD | Q16: SEA | R16: 700 | S16: 700 | T16: 46177 | U16: 46188 | V16: 46193
A17: PP-BONTAN-007 | B17: SINGLE | C17: 1 | D17: 700 | E17: 3000 | F17: =MAX(1,CEILING(D17/E17,1)) -> 1 | G17: 1004030360 | H17: TBA | I17: 1001030360 | J17: Bontang | K17: EUP EDIBLE OIL BONTANG | L17: CIF | M17: CPO | N17: HENRISON INTI PERSADA PT. | O17: CAPITOL | P17: FS | Q17: SEA | R17: 700 | S17: 700 | T17: 46178 | U17: 46193 | V17: 46207
A18: PP-BONTAN-008 | B18: SINGLE | C18: 1 | D18: 93 | E18: 3000 | F18: =MAX(1,CEILING(D18/E18,1)) -> 1 | G18: 1004030427 | H18: 056/MJR-PJB/CPO/06-2026 | I18: 1001030427 | J18: Bontang | K18: EUP EDIBLE OIL BONTANG | L18: CIF | M18: CPO | N18: MERBAUJAYA INDAHRAYA PT. | O18: AMERBAU | P18: FS | Q18: SEA | R18: 2300 | S18: 93.47 | T18: 46178 | U18: 46193 | V18: 46198
A19: PP-BONTAN-009 | B19: SINGLE | C19: 1 | D19: 3000 | E19: 3000 | F19: =MAX(1,CEILING(D19/E19,1)) -> 1 | G19: 1004030944 | H19: 020/TBP-EUP/CIF-CPO/07/26 | I19: 1001030944 | J19: Bontang | K19: EUP EDIBLE OIL BONTANG | L19: CIF | M19: CPO | N19: TANJUNG BUYU PERKASA PLANTATION PT. | O19: TELADAN_P | P19: FS | Q19: SEA | R19: 3000 | S19: 3000 | T19: 46205 | U19: 46208 | V19: 46213
A20: PP-BONTAN-010 | B20: SINGLE | C20: 1 | D20: 2000 | E20: 3000 | F20: =MAX(1,CEILING(D20/E20,1)) -> 1 | G20: 1004030361 | H20: 003/CPO/THL-JKT/KP/VI/2026 | I20: 1001030361 | J20: Bontang | K20: EUP EDIBLE OIL BONTANG | L20: CIF | M20: CPO | N20: TRIDAYA HUTAN LESTARI PT. | O20: ATRIHULES | P20: FS | Q20: SEA | R20: 2000 | S20: 2000 | T20: 46178 | U20: 46208 | V20: 46211 | W20: PP-BONTAN-014
A21: PP-BONTAN-011 | B21: SINGLE | C21: 1 | D21: 300 | E21: 3000 | F21: =MAX(1,CEILING(D21/E21,1)) -> 1 | G21: 1004030968 | H21: 1172000000542 | I21: 1001030968 | J21: Bontang | K21: EUP EDIBLE OIL BONTANG | L21: FOB | M21: CPO | N21: WAHANA KARYA SEJAHTERA MANDIRI PT. | O21: INTERCO | P21: MB | Q21: SEA | R21: 300 | S21: 300 | T21: 46206 | U21: 46208 | V21: 46218 | W21: PP-BONTAN-004, PP-BONTAN-005
A22: PP-BONTAN-012 | B22: SINGLE | C22: 1 | D22: 1300 | E22: 3000 | F22: =MAX(1,CEILING(D22/E22,1)) -> 1 | G22: 1004030926 | H22: 010/TBP-EUP/CIF-PK/07/26 | I22: 1001030926 | J22: Bontang | K22: EUP EDIBLE OIL BONTANG | L22: CIF | M22: PK | N22: TANJUNG BUYU PERKASA PLANTATION PT. | O22: TELADAN_P | P22: FS | Q22: SEA | R22: 1300 | S22: 1300 | T22: 46204 | U22: 46208 | V22: 46213
A23: PP-BONTAN-013 | B23: SINGLE | C23: 1 | D23: 2000 | E23: 3000 | F23: =MAX(1,CEILING(D23/E23,1)) -> 1 | G23: 1004030461 | H23: 004/CPO/IKSJ-JKT/KP/VI/2026 | I23: 1001030461 | J23: Bontang | K23: EUP EDIBLE OIL BONTANG | L23: CIF | M23: CPO | N23: INTI KEBUN SEJAHTERA PT. | O23: CAA | P23: FS | Q23: SEA | R23: 2000 | S23: 2000 | T23: 46184 | U23: 46209 | V23: 46215
A24: PP-BONTAN-014 | B24: SINGLE | C24: 1 | D24: 1300 | E24: 3000 | F24: =MAX(1,CEILING(D24/E24,1)) -> 1 | G24: 1004031047 | H24: 004/CPO/THL-JKT/KP/VII/2026 | I24: 1001031047 | J24: Bontang | K24: EUP EDIBLE OIL BONTANG | L24: CIF | M24: CPO | N24: TRIDAYA HUTAN LESTARI PT. | O24: ATRIHULES | P24: FS | Q24: SEA | R24: 1300 | S24: 1300 | T24: 46210 | U24: 46218 | V24: 46220 | W24: PP-BONTAN-010
A25: PP-BONTAN-015 | B25: SINGLE | C25: 1 | D25: 250 | E25: 3000 | F25: =MAX(1,CEILING(D25/E25,1)) -> 1 | G25: 1004031223 | H25: 1172000000544 | I25: 1001031223 | J25: Bontang | K25: EUP EDIBLE OIL BONTANG | L25: FOB | M25: PK | N25: WAHANA KARYA SEJAHTERA MANDIRI PT. | O25: INTERCO | P25: MB | Q25: SEA | R25: 250 | S25: 250 | T25: 46218 | U25: 46218 | V25: 46225 | W25: PP-BONTAN-020
A26: PP-BONTAN-016 | B26: SINGLE | C26: 1 | D26: 1000 | E26: 3000 | F26: =MAX(1,CEILING(D26/E26,1)) -> 1 | G26: 1004031296 | H26: TBA | I26: 1001031296 | J26: Bontang | K26: EUP EDIBLE OIL BONTANG | L26: FOB | M26: CPO | N26: MAJU KALIMANTAN HADAPAN PT | O26: AMAKAHA | P26: LT | Q26: SEA | R26: 1000 | S26: 1000 | T26: 46220 | U26: 46220 | V26: 46233
A27: PP-BONTAN-017 | B27: SINGLE | C27: 1 | D27: 300 | E27: 3000 | F27: =MAX(1,CEILING(D27/E27,1)) -> 1 | G27: 1004031352 | H27: TBA | I27: 1001031352 | J27: Bontang | K27: EUP EDIBLE OIL BONTANG | L27: FOB | M27: CPO | N27: UNGGUL WIDYA TEKNOLOGI LESTARI PT. | O27: AUNWITELES | P27: LT | Q27: SEA | R27: 300 | S27: 300 | T27: 46224 | U27: 46226 | V27: 46228
A28: PP-BONTAN-018 | B28: SINGLE | C28: 1 | D28: 3000 | E28: 3000 | F28: =MAX(1,CEILING(D28/E28,1)) -> 1 | G28: 1004031065 | H28: 028/TLN-EUP/CIF-CPO/07/26 | I28: 1001031065 | J28: Bontang | K28: EUP EDIBLE OIL BONTANG | L28: CIF | M28: CPO | N28: TELEN PT. | O28: TELADAN_P | P28: FS | Q28: SEA | R28: 3000 | S28: 3000 | T28: 46210 | U28: 46228 | V28: 46233 | W28: PP-BONTAN-019
A29: PP-BONTAN-019 | B29: SINGLE | C29: 1 | D29: 3000 | E29: 3000 | F29: =MAX(1,CEILING(D29/E29,1)) -> 1 | G29: 1004031036 | H29: TBA | I29: 1001031036 | J29: Bontang | K29: EUP EDIBLE OIL BONTANG | L29: CIF | M29: CPO | N29: TELEN PRIMA SAWIT PT | O29: TELADAN_P | P29: FS | Q29: SEA | R29: 3000 | S29: 3000 | T29: 46210 | U29: 46228 | V29: 46233 | W29: PP-BONTAN-018
A30: PP-BONTAN-020 | B30: SINGLE | C30: 1 | D30: 250 | E30: 3000 | F30: =MAX(1,CEILING(D30/E30,1)) -> 1 | G30: 1004030888 | H30: 1172000000540 | I30: 1001030888 | J30: Bontang | K30: EUP EDIBLE OIL BONTANG | L30: FOB | M30: PK | N30: WAHANA KARYA SEJAHTERA MANDIRI PT. | O30: INTERCO | P30: MB | Q30: SEA | R30: 250 | S30: 250 | T30: 46203 | U30: 46228 | V30: 46235 | W30: PP-BONTAN-015
A31: PP-BONTAN-021 | B31: SINGLE | C31: 1 | D31: 1700 | E31: 3000 | F31: =MAX(1,CEILING(D31/E31,1)) -> 1 | G31: 1004031090 | H31: 007/TJIM-EUP/PK/VII/2026 | I31: 1001031090 | J31: Bontang | K31: EUP EDIBLE OIL BONTANG | L31: CIF | M31: PK | N31: TIMURJAYA INDOMAKMUR PT. | O31: ATIMURJAYA | P31: FS | Q31: SEA | R31: 1700 | S31: 1700 | T31: 46212 | U31: 46232 | V31: 46238
A32: PP-BONTAN-022 | B32: SINGLE | C32: 1 | D32: 3000 | E32: 3000 | F32: =MAX(1,CEILING(D32/E32,1)) -> 1 | G32: 1004031089 | H32: 009/TJIM-EUP/CPO/VII/2026 | I32: 1001031089 | J32: Bontang | K32: EUP EDIBLE OIL BONTANG | L32: CIF | M32: CPO | N32: TIMURJAYA INDOMAKMUR PT. | O32: ATIMURJAYA | P32: FS | Q32: SEA | R32: 3000 | S32: 3000 | T32: 46212 | U32: 46234 | V32: 46240 | W32: PP-BONTAN-028
A33: PP-BONTAN-023 | B33: SINGLE | C33: 1 | D33: 4000 | E33: 4000 | F33: =MAX(1,CEILING(D33/E33,1)) -> 1 | G33: 1004031325 | H33: TBA | I33: 1001031325 | J33: Bontang | K33: EUP EDIBLE OIL BONTANG | L33: CIF | M33: CPO | N33: REA KALTIM PLANTATIONS PT. | O33: REA | P33: LT | Q33: SEA | R33: 4000 | S33: 4000 | T33: 46223 | U33: 46234 | V33: 46235
A34: PP-BONTAN-024 | B34: SINGLE | C34: 1 | D34: 1400 | E34: 3000 | F34: =MAX(1,CEILING(D34/E34,1)) -> 1 | G34: 1004030943 | H34: 004/HIP/EUP-CРO/VII/2026 | I34: 1001030943 | J34: Bontang | K34: EUP EDIBLE OIL BONTANG | L34: CIF | M34: CPO | N34: HENRISON INTI PERSADA PT. | O34: CAPITOL | P34: FS | Q34: SEA | R34: 1400 | S34: 1400 | T34: 46205 | U34: 46235 | V34: 46239 | W34: PP-BONTAN-025
A35: PP-BONTAN-025 | B35: SINGLE | C35: 1 | D35: 1600 | E35: 3000 | F35: =MAX(1,CEILING(D35/E35,1)) -> 1 | G35: 1004030942 | H35: 007/MHS/EUP-CPO/VII/2026 | I35: 1001030942 | J35: Bontang | K35: EUP EDIBLE OIL BONTANG | L35: CIF | M35: CPO | N35: MEDCOPAPUA HIJAU SELARAS PT. | O35: CAPITOL | P35: FS | Q35: SEA | R35: 1600 | S35: 1600 | T35: 46205 | U35: 46235 | V35: 46239 | W35: PP-BONTAN-024
A36: PP-BONTAN-026 | B36: SINGLE | C36: 1 | D36: 1000 | E36: 3000 | F36: =MAX(1,CEILING(D36/E36,1)) -> 1 | G36: 1004031291 | H36: 1182000000368 | I36: 1001031291 | J36: Bontang | K36: EUP EDIBLE OIL BONTANG | L36: FOB | M36: WASTE OIL (POME) | N36: AGRIPRIMA CIPTA PERSADA PT. | O36: INTERCO | P36: MB | Q36: SEA | R36: 1000 | S36: 1000 | T36: 46220 | U36: 46235 | V36: 46242
A37: PP-BONTAN-027 | B37: SINGLE | C37: 1 | D37: 300 | E37: 3000 | F37: =MAX(1,CEILING(D37/E37,1)) -> 1 | G37: 1004031279 | H37: 1162000000408 | I37: 1001031279 | J37: Bontang | K37: EUP EDIBLE OIL BONTANG | L37: FOB | M37: CPO | N37: HARAPAN SAWIT SEJAHTERAH PT. | O37: INTERCO | P37: MB | Q37: SEA | R37: 300 | S37: 300 | T37: 46220 | U37: 46241 | V37: 46249 | W37: PP-BONTAN-031, PP-BONTAN-032, PP-BONTAN-033
A38: PP-BONTAN-028 | B38: SINGLE | C38: 1 | D38: 3500 | E38: 3500 | F38: =MAX(1,CEILING(D38/E38,1)) -> 1 | G38: 1004031355 | H38: TBA | I38: 1001031355 | J38: Bontang | K38: EUP EDIBLE OIL BONTANG | L38: CIF | M38: CPO | N38: TIMURJAYA INDOMAKMUR PT. | O38: ATIMURJAYA | P38: FS | Q38: SEA | R38: 3500 | S38: 3500 | T38: 46224 | U38: 46244 | V38: 46248 | W38: PP-BONTAN-022
A39: PP-BONTAN-029 | B39: SINGLE | C39: 1 | D39: 3000 | E39: 3000 | F39: =MAX(1,CEILING(D39/E39,1)) -> 1 | G39: 1004031327 | H39: TBA | I39: 1001031327 | J39: Bontang | K39: EUP EDIBLE OIL BONTANG | L39: CIF | M39: CPO | N39: TANJUNG BUYU PERKASA PLANTATION PT. | O39: TELADAN_P | P39: FS | Q39: SEA | R39: 3000 | S39: 3000 | T39: 46223 | U39: 46244 | V39: 46249
A40: PP-BONTAN-030 | B40: SINGLE | C40: 1 | D40: 2000 | E40: 3000 | F40: =MAX(1,CEILING(D40/E40,1)) -> 1 | G40: 1004031235 | H40: 1310002558 | I40: 1001031235 | J40: Bontang | K40: EUP EDIBLE OIL BONTANG | L40: FOB | M40: CPO | N40: DHARMA INTISAWIT NUGRAHA PT. | O40: DSN | P40: LT | Q40: SEA | R40: 2000 | S40: 2000 | T40: 46218 | U40: 46247 | V40: 46249
...
